Workbook

Sheet Rate Sheet
A3: To Request Emergency Response Services Please Contact Your BioRemedy Representative Or Email The Emergency Response Inbox At ER@BioRemedy.com
A4: Standard Rates | C4: for work performed Monday through Friday between the hours of 8:00 AM and 5:00 PM.
A5: Overtime Rates | C5: for work performed outside the standard work hours and all Saturdays and Sundays.
A6: Emergency Rates | C6: for any work that is considered an emergency regardless of when work is performed.
A7: Double Time Rates | C7: applies to all work performed on a holiday
A8: Holidays are New Years Eve, New Years Day, Easter, Memorial Day, Independence Day, Labor Day, Thanksgiving, Black Friday, Christmas Eve and Christmas Day.
B9: BioRemedy RATE SHEET
A10: ** There is a Four Hour Minimum for Labor, Trucks, & Equipment on Emergency Call Outs **
A11: Section I: Labor Rates | H11: Standard Rate | I11: Emergency/ OT Rate | J11: Double Time Rate | K11: Unit of Measure
A12: Administration | H12: 35 | I12: 35 | J12: 35 | K12: Hourly
A13: Disposal Coordinator | H13: 70 | I13: =IF(ISNUMBER(Sheet5!I13),IFERROR(H13*1.5,Sheet5!I13),Sheet5!I13) -> 105 | J13: =H13*2 -> 140 | K13: Hourly
A14: Site Safety Coordinator | H14: 119 | I14: =IF(ISNUMBER(Sheet5!I15),IFERROR(H14*1.5,Sheet5!I15),Sheet5!I15) -> 178.5 | J14: =H14*2 -> 238 | K14: Hourly
A15: Microbial Consultant | H15: 103 | I15: =IF(ISNUMBER(Sheet5!I16),IFERROR(H15*1.5,Sheet5!I16),Sheet5!I16) -> 154.5 | J15: =H15*2 -> 206 | K15: Hourly
A16: Senior Project Manager/ER Manager/IC | H16: 92 | I16: =IF(ISNUMBER(Sheet5!I17),IFERROR(H16*1.5,Sheet5!I17),Sheet5!I17) -> 138 | J16: =H16*2 -> 184 | K16: Hourly
A17: Supervisor | H17: 85 | I17: =IF(ISNUMBER(Sheet5!I18),IFERROR(H17*1.5,Sheet5!I18),Sheet5!I18) -> 127.5 | J17: =H17*2 -> 170 | K17: Hourly
A18: Foreman | H18: 75 | I18: =IF(ISNUMBER(Sheet5!I19),IFERROR(H18*1.5,Sheet5!I19),Sheet5!I19) -> 112.5 | J18: =H18*2 -> 150 | K18: Hourly
A19: Technician ‐ HazMat trained, Confined Space Certified | H19: 65 | I19: =IF(ISNUMBER(Sheet5!I20),IFERROR(H19*1.5,Sheet5!I20),Sheet5!I20) -> 97.5 | J19: =H19*2 -> 130 | K19: Hourly
A20: Recovery Truck Operator | H20: 83 | I20: =IF(ISNUMBER(Sheet5!I21),IFERROR(H20*1.5,Sheet5!I21),Sheet5!I21) -> 124.5 | J20: =H20*2 -> 166 | K20: Hourly
A21: Heavy Equipment Operator | H21: 75 | I21: =IF(ISNUMBER(Sheet5!I22),IFERROR(H21*1.5,Sheet5!I22),Sheet5!I22) -> 112.5 | J21: =H21*2 -> 150 | K21: Hourly
A22: CDL Truck Driver | H22: 65 | I22: =IF(ISNUMBER(Sheet5!I23),IFERROR(H22*1.5,Sheet5!I23),Sheet5!I23) -> 97.5 | J22: =H22*2 -> 130 | K22: Hourly
A23: Mechanic | H23: 70 | I23: =IF(ISNUMBER(Sheet5!I24),IFERROR(H23*1.5,Sheet5!I24),Sheet5!I24) -> 105 | J23: =H23*2 -> 140 | K23: Hourly
A24: Lodging | H24: 200 | I24: =IF(ISNUMBER(Sheet5!I25),IFERROR(H24*1.5,Sheet5!I25),Sheet5!I25) -> 300 | J24: 300 | K24: Per Man Per Day
A25: Per Diem | H25: 70 | I25: =IF(ISNUMBER(Sheet5!I26),IFERROR(H25*1.5,Sheet5!I26),Sheet5!I26) -> 105 | J25: 100 | K25: Per Man Per Day
A26: Section II: Equipment and Materials (All Fuel Burning Equipment Will Be Subject To A Fuel Surcharge)
A27: Hydro Super Vac | H27: Cost +28% Margin | I27: Cost +28% Margin | J27: Cost+28% Margin | K27: Hourly
A28: Microbial Spray Trailer | H28: =Sheet5!H29*0.9 -> 315 | I28: N/A | J28: N/A | K28: Daily
A29: Environmental CyberResponse Unit | H29: =Sheet5!H30*0.9 -> 270 | I29: N/A | J29: N/A | K29: Daily
A30: HazMat Recovery Truck | H30: 250 | I30: N/A | J30: N/A | K30: Hourly
A31: 3/4 Ton or 1 Ton Pick‐Up Truck | H31: 300 | I31: N/A | J31: N/A | K31: Daily
A32: Pick‐Up Truck (1/2 or smaller) | H32: =Sheet5!H34*0.9 -> 180 | I32: N/A | J32: N/A | K32: Daily
A33: Vactron | H33: 80 | I33: N/A | J33: N/A | K33: Hourly
A34: Toll Tag Fees – Two Axle | H34: Cost + 10% Margin | I34: N/A | J34: N/A | K34: Each
A35: Toll Tag Fees ‐ Four Axels | H35: Cost + 10% Margin | I35: N/A | J35: N/A | K35: Each
A36: Drone Service (includes Operator) | H36: 150 | I36: 150 | J36: 150 | K36: Hourly
A37: Tractor w/ Van Trailer or Flatbed (Includes Operator) | H37: =Sheet5!H38*0.9 -> 117 | I37: 160 | J37: 205 | K37: Hourly
A38: Tractor w/ Dbl Rolloff Trailer | H38: Cost +28% Margin | I38: Cost +28% Margin | J38: Cost +28% Margin | K38: Hourly
A39: BIOREMEDY Bobtail Roll‐Off Truck/Driver (Includes Operator) | H39: =Sheet5!H40*0.9 -> 135 | I39: 185 | J39: 225 | K39: Hourly
A40: BIOREMEDY 100 bbl. Vacuum Truck (Includes Operator) | H40: 155 | I40: 195 | J40: 245 | K40: Hourly
A41: 70 bbl. Vacuum Truck (Includes Operator) | H41: 140 | I41: 175 | J41: 215 | K41: Hourly
A42: Tractor w/ 130 bbl. Vacuum Tanker (Includes Operator) | H42: =Sheet5!H43*0.9 -> 148.5 | I42: 200 | J42: 245 | K42: Hourly
...

Sheet Sheet5
A3: To Request Emergency Response Services Please Contact Your BioRemedy Representative Or Email The Emergency Response Inbox At ER@BioRemedy.com
A4: Standard Rates | C4: for work performed Monday through Friday between the hours of 8:00 AM and 5:00 PM.
A5: Overtime Rates | C5: for work performed outside the standard work hours and all Saturday's and Sunday's.
A6: Emergency Rates | C6: for any work that is considered an emergency regardless of when work is performed.
A7: Double Time Rates | C7: applies to all work performed on a holiday
A8: BioRemedy's holidays are New Years Eve, New Years Day, Easter, Memorial Day, Independence Day, Labor Day, Thanksgiving, Black Friday, Christmas Eve and Christmas Day.
A10: ** There is a Four Hour Minimum for Labor, Trucks, & Equipment on Emergency Call Outs **
A11: Section I: Labor Rates | H11: Standard Rate | I11: Emergency/ OT Rate | J11: Double Time Rate | K11: Unit of Measure
A12: Administration | H12: 68 | I12: =H12*1.5 -> 102 | J12: =H12*2 -> 136 | K12: Hourly | M12: =IF(ISNUMBER(I12),IFERROR(H12*1.5,I12),I12) -> 102
A13: Disposal Coordinator | H13: 65 | I13: =H13*1.5 -> 97.5 | J13: =H13*2 -> 130 | K13: Hourly
A14: Resource/Logistics Coordinator | H14: 60 | I14: =H14*1.5 -> 90 | J14: =H14*2 -> 120 | K14: Hourly
A15: Site Safety Coordinator | H15: 110 | I15: =H15*1.5 -> 165 | J15: =H15*2 -> 220 | K15: Hourly
A16: Microbial Consultant | H16: 95 | I16: =H16*1.5 -> 142.5 | J16: =H16*2 -> 190 | K16: Hourly
A17: Senior Project Manager/ER Manager/IC | H17: 85 | I17: =H17*1.5 -> 127.5 | J17: =H17*2 -> 170 | K17: Hourly
A18: Supervisor | H18: 80 | I18: =H18*1.5 -> 120 | J18: =H18*2 -> 160 | K18: Hourly
A19: Foreman | H19: 70 | I19: =H19*1.5 -> 105 | J19: =H19*2 -> 140 | K19: Hourly
A20: Technician ‐ HazMat trained, Confined Space Certified | H20: 60 | I20: =H20*1.5 -> 90 | J20: =H20*2 -> 120 | K20: Hourly
A21: Recovery Truck Operator | H21: 78 | I21: =H21*1.5 -> 117 | J21: =H21*2 -> 156 | K21: Hourly
A22: Heavy Equipment Operator | H22: 80 | I22: =H22*1.5 -> 120 | J22: =H22*2 -> 160 | K22: Hourly
A23: CDL Truck Driver | H23: 75 | I23: =H23*1.5 -> 112.5 | J23: =H23*2 -> 150 | K23: Hourly
A24: Mechanic | H24: 65 | I24: =H24*1.5 -> 97.5 | J24: =H24*2 -> 130 | K24: Hourly
A25: Lodging | H25: 200 | I25: 200 | J25: 300 | K25: Per Man Per Day
A26: Per Diem | H26: 70 | I26: 70 | J26: 100 | K26: Per Man Per Day
A27: Section II: Equipment and Materials (All Fuel Burning Equipment Will Be Subject To A Fuel Surcharge)
A28: Hydro Super Vac | H28: 400 | I28: N/A | J28: N/A | K28: Hourly
A29: Microbial Spray Trailer | H29: 350 | I29: N/A | J29: N/A | K29: Daily
A30: Environmental CyberResponse Unit | H30: 300 | I30: N/A | J30: N/A | K30: Daily
A31: HazMat Recovery Truck | H31: 225 | I31: N/A | J31: N/A | K31: Hourly
A32: Service/Mechanic Truck | H32: 55 | I32: N/A | J32: N/A | K32: Hourly
A33: 3/4 Ton or 1 Ton Pick‐Up/ Dually Truck | H33: 300 | I33: N/A | J33: N/A | K33: Daily
A34: Pick‐Up Truck (1/2 or smaller) | H34: 200 | I34: N/A | J34: N/A | K34: Daily
A35: Vactron | H35: 75 | I35: N/A | J35: N/A | K35: Hourly
A36: Toll Tag Fees – Two Axle | H36: 35 | I36: N/A | J36: N/A | K36: Each
A37: Toll Tag Fees ‐ Four Axels | H37: 55 | I37: N/A | J37: N/A | K37: Each
A38: Tractor w/ Van Trailer or Flatbed (Includes Operator) | H38: 130 | I38: 160 | J38: 205 | K38: Hourly
A39: Tractor w/ Dbl Rolloff Trailer | H39: 135 | I39: 165 | J39: 210 | K39: Hourly
A40: BIOREMEDY Bobtail Roll‐Off Truck/Driver (Includes Operator) | H40: 150 | I40: 185 | J40: 225 | K40: Hourly
A41: 100 bbl. Vacuum Truck (Includes Operator) | H41: 150 | I41: 185 | J41: 225 | K41: Hourly
A42: 70 bbl. Vacuum Truck (Includes Operator) | H42: 140 | I42: 175 | J42: 215 | K42: Hourly
A43: Tractor w/ 130 bbl. Vacuum Tanker (Includes Operator) | H43: 165 | I43: 200 | J43: 245 | K43: Hourly
...
